import { Router, Request, Response } from "express";
import { body, validationResult } from "express-validator";
import { RequestValidationError } from '../errors/request-validation-error';
import { DatabaseConnectionError } from '../errors/database-connection-error';
import User from "../models/user";
import { BadRequestError } from '../errors/badrequest-error';

const router = Router();

router.post("/api/users/signup", [
    body("email").isEmail().withMessage("El email debe ser vÃ¡lido"),
    body("password").trim().isLength({ min: 4, max: 20 }).withMessage("El password debe contener entre 4 y 20 caracteres")
], async (req: Request, res: Response) => {

    const errors = validationResult(req);

    if (!errors.isEmpty()) {
       // return res.status(400).send(errors.array());
    
        throw new RequestValidationError(errors.array()) // La informacion que se envia en el constructor de la
        // clase error, es la propiedad message cuando el error es manejado en algun catch o middleware que recibe el
        // error como parametro de funcion
    }

    const { email, password } = req.body;

    const exists = await User.findOne({email});

    if(exists) {
        console.log("Email en uso");
        throw new BadRequestError("El usuario ya existe");
    }

    const user = await (User.build({
        email,
        password
    })).save();
    
    res.status(201).send(user);
})

export { router as signupRouter }